Workbook

Sheet 社長報告08_05
B1: 採用活動 日次報告書
B2: ="報告日：" & TEXT(MAX(日次レポート!$A$4:$A$200),"yyyy年m月d日") & " ｜ 短時間勤務者（成田NRT・千歳CTS） ｜ 宛先：社長" -> 報告日：2026年8月6日 ｜ 短時間勤務者（成田NRT・千歳CTS） ｜ 宛先：社長
B3: 担当者：遠藤
B5: 承諾（採用） | D5: 応募数（累計） | F5: 面接実施（累計）
B6: =KPIダッシュボード!D16&" / "&KPIダッシュボード!C16&" 名" -> 0 / 20 名 | D6: =KPIダッシュボード!D11&" 名" -> 20 名 | F6: =KPIダッシュボード!D14&" 名" -> 1 名
B8: =" 達成率 "&TEXT(KPIダッシュボード!E16,"0.0%")&" 前日比 "&TEXT(KPIダッシュボード!G16,"+0;-0;0") -> 達成率 0.0% 前日比 0 | D8: =" 目標 "&KPIダッシュボード!C11&" 達成率 "&TEXT(KPIダッシュボード!E11,"0.0%")&" 前日比 "&TEXT(KPIダッシュボード!G11,"+0;-0;0") -> 目標 144 達成率 13.9% 前日比 +19 | F8: =" 目標 "&KPIダッシュボード!C14&" 前日比 "&TEXT(KPIダッシュボード!G14,"+0;-0;0") -> 目標 42 前日比 +1
B10: ■ 採用ファネル（目標 vs 実績）
B11: 指標 | C11: 目標 | D11: 実績 | E11: 達成率 | F11: 前日比
B12: 応募数 | C12: =KPIダッシュボード!C11 -> 144 | D12: =KPIダッシュボード!D11 -> 20 | E12: =KPIダッシュボード!E11 -> 0.13888889 | F12: =KPIダッシュボード!G11 -> 19
B13: 書類通過 | C13: =KPIダッシュボード!C12 -> 72 | D13: =KPIダッシュボード!D12 -> 4 | E13: =KPIダッシュボード!E12 -> 0.055555556 | F13: =KPIダッシュボード!G12 -> 4
B14: 面接設定 | C14: =KPIダッシュボード!C13 -> 50 | D14: =KPIダッシュボード!D13 -> 4 | E14: =KPIダッシュボード!E13 -> 0.08 | F14: =KPIダッシュボード!G13 -> 4
B15: 面接実施 | C15: =KPIダッシュボード!C14 -> 42 | D15: =KPIダッシュボード!D14 -> 1 | E15: =KPIダッシュボード!E14 -> 0.023809524 | F15: =KPIダッシュボード!G14 -> 1
B16: 内定 | C16: =KPIダッシュボード!C15 -> 25 | D16: =KPIダッシュボード!D15 -> 0 | E16: =KPIダッシュボード!E15 -> 0 | F16: =KPIダッシュボード!G15 -> 0
B17: 承諾 | C17: =KPIダッシュボード!C16 -> 20 | D17: =KPIダッシュボード!D16 -> 0 | E17: =KPIダッシュボード!E16 -> 0 | F17: =KPIダッシュボード!G16 -> 0
B19: ■ 拠点別 採用目標 達成（承諾）
B20: 拠点 | C20: 採用目標 | D20: 承諾実績 | E20: 達成率
B21: NRT（成田） | C21: =KPIダッシュボード!C44 -> 10 | D21: =KPIダッシュボード!D44 -> 0 | E21: =KPIダッシュボード!E44 -> 0
B22: CTS（千歳） | C22: =KPIダッシュボード!C45 -> 10 | D22: =KPIダッシュボード!D45 -> 0 | E22: =KPIダッシュボード!E45 -> 0
B23: 合計 | C23: =KPIダッシュボード!C46 -> 20 | D23: =KPIダッシュボード!D46 -> 0 | E23: =KPIダッシュボード!E46 -> 0
B25: ■ 応募者属性（累計）
B26: 男女 | C26: 人数 | D26: 比率 | E26: 国籍 | F26: 人数 | G26: 比率
B27: 男 | C27: =COUNTIF(応募者データ!$G$3:$G$504,"男") -> 11 | D27: =IFERROR(C27/SUM(C27:C28),"") -> 0.55 | E27: 日本 | F27: =COUNTIF(応募者データ!$H$3:$H$504,"日本") -> 16 | G27: =IFERROR(F27/SUM(F27:F28),"") -> 0.8
B28: 女 | C28: =COUNTIF(応募者データ!$G$3:$G$504,"女") -> 9 | D28: =IFERROR(C28/SUM(C27:C28),"") -> 0.45 | E28: 外国籍 | F28: =COUNTIF(応募者データ!$H$3:$H$504,"外国籍") -> 4 | G28: =IFERROR(F28/SUM(F27:F28),"") -> 0.2
B30: 経験 | C30: 人数 | D30: 比率 | E30: 就業区分 | F30: 人数 | G30: 比率
B31: 経験者 | C31: =COUNTIF(応募者データ!$I$3:$I$504,"経験者") -> 1 | D31: =IFERROR(C31/SUM(C31:C33),"") -> 0.05 | E31: 学生 | F31: =COUNTIF(応募者データ!$J$3:$J$504,"学生") -> 0 | G31: =IFERROR(F31/SUM(F31:F36),"") -> 0
B32: 未経験者 | C32: =COUNTIF(応募者データ!$I$3:$I$504,"未経験者") -> 19 | D32: =IFERROR(C32/SUM(C31:C33),"") -> 0.95 | E32: フリーター | F32: =COUNTIF(応募者データ!$J$3:$J$504,"フリーター") -> 0 | G32: =IFERROR(F32/SUM(F31:F36),"") -> 0
B33: 未入力 | C33: =COUNTA(応募者データ!$E$3:$E$504)-COUNTIF(応募者データ!$I$3:$I$504,"経験者")-COUNTIF(応募者データ!$I$3:$I$504,"未経験者") -> 0 | D33: =IFERROR(C33/SUM(C31:C33),"") -> 0 | E33: 社会人 | F33: =COUNTIF(応募者データ!$J$3:$J$504,"社会人") -> 0 | G33: =IFERROR(F33/SUM(F31:F36),"") -> 0
E34: 主婦・主夫 | F34: =COUNTIF(応募者データ!$J$3:$J$504,"主婦・主夫") -> 2 | G34: =IFERROR(F34/SUM(F31:F36),"") -> 0.1
E35: その他 | F35: =COUNTIF(応募者データ!$J$3:$J$504,"その他") -> 4 | G35: =IFERROR(F35/SUM(F31:F36),"") -> 0.2
E36: 未入力 | F36: =COUNTA(応募者データ!$E$3:$E$504)-COUNTIF(応募者データ!$J$3:$J$504,"学生")-COUNTIF(応募者データ!$J$3:$J$504,"フリーター")-COUNTIF(応募者データ!$J$3:$J$504,"社会人")-COUNTIF(応募者データ!$J$3:$J$504,"主婦・主夫")-COUNTIF(応募者データ!$J$3:$J$504,"その他") -> 14 | G36: =IFERROR(F36/SUM(F31:F36),"") -> 0.7
B38: 年齢分布 | C38: 〜19 | D38: 20代 | E38: 30代 | F38: 40代 | G38: 50代 | H38: 60〜
B39: 人数 | C39: =COUNTIF(応募者データ!$F$3:$F$504,"<=19") -> 4 | D39: =COUNTIFS(応募者データ!$F$3:$F$504,">=20",応募者データ!$F$3:$F$504,"<=29") -> 8 | E39: =COUNTIFS(応募者データ!$F$3:$F$504,">=30",応募者データ!$F$3:$F$504,"<=39") -> 2 | F39: =COUNTIFS(応募者データ!$F$3:$F$504,">=40",応募者データ!$F$3:$F$504,"<=49") -> 0 | G39: =COUNTIFS(応募者データ!$F$3:$F$504,">=50",応募者データ!$F$3:$F$504,"<=59") -> 1 | H39: =COUNTIF(応募者データ!$F$3:$F$504,">=60") -> 5
B41: ■ 特記事項・本日の動き（担当者記入）
B42: ・現在の応募者数は17名、うち面接予定は2名です。 ・内山さんが新たな採用ルートとして「ナリタJOBサポート」を開拓し、同ルート経由で旅客業務経験者（28歳・日本人女性）1名の応募がありました。現在、選考を進める予定です。 ・ネオキャリアの求人原稿を一部修正した結果、主婦層と思われる応募（62歳女性・経験有無確認中）があり、応募層の広がりが見られています。 ・プロジェクトメンバーの役割分担を整理し、制度設計（交通費、雇用形態、契約期間等）については、高田部長・坂本を中心に検討を進める体制としました。 【現在の課題】 短時間勤務希望者の採用を進めるにあたり、①本社研修（7日間・56時間）の教育体制、②交通費規程（週3日程度の勤務では現行規程上、自己負担が発生するケースがある）をはじめとした制度面の整理が必要と考えております。 引き続き、応募状況を確認しながら、媒体改善と制度設計を並行して進めてまいります。
B61: ■ Issue / Action Tracker（課題・アクション管理）
B62: コンサル標準の課題管理表｜Action・TODO・Responsible・STATUS・DUE DATE｜更新日：2026-08-08｜出典：担当ヒアリング（Issue/Action Tracker）
B63: 課題 / Action | C63: TODO（次にやること） | D63: Responsible | E63: STATUS（進捗状況） | F63: DUE DATE
B64: 1 社員紹介制度の開始 | C64: 稟議を上程・決裁を取得し、制度を正式スタート | D64: 遠藤・髙田 | E64: 稟議準備中。現場説明・協力依頼済 | F64: 8/14
B65: 2 交通費ルールの整理 | C65: 短時間勤務者向けの交通費取扱いを確定・規程化 | D65: 髙田・坂本 | E65: 短時間勤務者向け取扱いを検討中 | F65: 8/14
B66: 3 既存パート時給の見直し | C66: UL等 既存者との時給差の是正方針を決定 | D66: 髙田・坂本 | E66: UL等、既存者との時給差を確認中 | F66: 8/14
...

Sheet KPIダッシュボード
B1: 📊 短時間勤務者 採用KPIダッシュボード
B2: =TEXT(MAX(日次レポート!$A$4:$A$200),"yyyy/mm/dd")&" 時点 ｜ 成田(NRT)・千歳(CTS) パート採用進捗 ｜ 数値は応募者データより自動集計" -> 2026/08/06 時点 ｜ 成田(NRT)・千歳(CTS) パート採用進捗 ｜ 数値は応募者データより自動集計
B4: ◎ 目標設定 ─ 黄色セルに入力（採用目標から各段階の目標を自動逆算）
B5: 採用目標（承諾・人） | C5: NRT(成田) | D5: 10 | E5: CTS(千歳) | F5: 10 | G5: 合計 | H5: =D5+F5 -> 20
B6: 歩留まり前提 | C6: 書類通過率 | D6: 面接設定率 | E6: 面接実施率 | F6: 内定率 | G6: 承諾率
B7: （応募→承諾） | C7: 0.5 | D7: 0.7 | E7: 0.85 | F7: 0.6 | G7: 0.8
B9: ① 採用ファネル：目標(逆算) vs 実績（累計）
B10: 指標 | C10: 目標(逆算) | D10: 実績(累計) | E10: 達成率 | F10: 前日 | G10: 前日比
B11: 応募数 | C11: =ROUNDUP(C12/$C$7,0) -> 144 | D11: =COUNTA(応募者データ!$E$3:$E$504) -> 20 | E11: =IFERROR(D11/C11,"") -> 0.13888889 | F11: =IFERROR(LOOKUP(1E+100,日次レポート!B$4:B$200),0) -> 1 | G11: =D11-F11 -> 19
B12: 書類通過 | C12: =ROUNDUP(C13/$D$7,0) -> 72 | D12: =COUNTIF(応募者データ!$K$3:$K$504,"通過") -> 4 | E12: =IFERROR(D12/C12,"") -> 0.055555556 | F12: =IFERROR(LOOKUP(1E+100,日次レポート!C$4:C$200),0) -> 0 | G12: =D12-F12 -> 4
B13: 面接設定 | C13: =ROUNDUP(C14/$E$7,0) -> 50 | D13: =COUNTIF(応募者データ!$N$3:$N$504,"面接調整中")+COUNTIF(応募者データ!$N$3:$N$504,"面接日確定")+COUNTIF(応募者データ!$N$3:$N$504,"面接実施済み") -> 4 | E13: =IFERROR(D13/C13,"") -> 0.08 | F13: =IFERROR(LOOKUP(1E+100,日次レポート!D$4:D$200),0) -> 0 | G13: =D13-F13 -> 4
B14: 面接実施 | C14: =ROUNDUP(C15/$F$7,0) -> 42 | D14: =COUNTIF(応募者データ!$N$3:$N$504,"面接実施済み") -> 1 | E14: =IFERROR(D14/C14,"") -> 0.023809524 | F14: =IFERROR(LOOKUP(1E+100,日次レポート!E$4:E$200),0) -> 0 | G14: =D14-F14 -> 1
B15: 内定 | C15: =ROUNDUP(C16/$G$7,0) -> 25 | D15: =COUNTIF(応募者データ!$Q$3:$Q$504,"採用")+COUNTIF(応募者データ!$Q$3:$Q$504,"入社予定")+COUNTIF(応募者データ!$Q$3:$Q$504,"採用辞退")+COUNTIF(応募者データ!$Q$3:$Q$504,"入社辞退") -> 0 | E15: =IFERROR(D15/C15,"") -> 0 | F15: =IFERROR(LOOKUP(1E+100,日次レポート!F$4:F$200),0) -> 0 | G15: =D15-F15 -> 0
B16: 承諾 | C16: =$H$5 -> 20 | D16: =COUNTIF(応募者データ!$Q$3:$Q$504,"採用")+COUNTIF(応募者データ!$Q$3:$Q$504,"入社予定") -> 0 | E16: =IFERROR(D16/C16,"") -> 0 | F16: =IFERROR(LOOKUP(1E+100,日次レポート!G$4:G$200),0) -> 0 | G16: =D16-F16 -> 0
B18: ② 転換率（歩留まり）
B19: 指標 | C19: 値 | D19: 計算式・定義
B20: 書類通過率 | C20: =IFERROR(D12/D11,"") -> 0.2 | D20: 書類通過 ÷ 応募数
B21: 面接設定率 | C21: =IFERROR(D13/D12,"") -> 1 | D21: 面接設定 ÷ 書類通過
B22: 面接実施率 | C22: =IFERROR(D14/D13,"") -> 0.25 | D22: 面接実施 ÷ 面接設定
B23: 内定率 | C23: =IFERROR(D15/D14,"") -> 0 | D23: 内定 ÷ 面接実施
B24: 承諾率 | C24: =IFERROR(D16/D15,"") | D24: 承諾 ÷ 内定
B26: ③ 媒体別 実績
B27: 媒体 | C27: 応募数 | D27: 書類通過 | E27: 面接設定 | F27: 面接実施 | G27: 内定 | H27: 承諾
B28: バイトル | C28: =COUNTIFS(応募者データ!$B$3:$B$504,"バイトル") -> 16 | D28: =COUNTIFS(応募者データ!$B$3:$B$504,"バイトル",応募者データ!$K$3:$K$504,"通過") -> 2 | E28: =COUNTIFS(応募者データ!$B$3:$B$504,"バイトル",応募者データ!$N$3:$N$504,"面接調整中")+COUNTIFS(応募者データ!$B$3:$B$504,"バイトル",応募者データ!$N$3:$N$504,"面接日確定")+COUNTIFS(応募者データ!$B$3:$B$504,"バイトル",応募者データ!$N$3:$N$504,"面接実施済み") -> 2 | F28: =COUNTIFS(応募者データ!$B$3:$B$504,"バイトル",応募者データ!$N$3:$N$504,"面接実施済み") -> 1 | G28: =COUNTIFS(応募者データ!$B$3:$B$504,"バイトル",応募者データ!$Q$3:$Q$504,"採用")+COUNTIFS(応募者データ!$B$3:$B$504,"バイトル",応募者データ!$Q$3:$Q$504,"入社予定")+COUNTIFS(応募者データ!$B$3:$B$504,"バイトル",応募者データ!$Q$3:$Q$504,"採用辞退")+COUNTIFS(応募者データ!$B$3:$B$504,"バイトル",応募者データ!$Q$3:$Q$504,"入社辞退") -> 0 | H28: =COUNTIFS(応募者データ!$B$3:$B$504,"バイトル",応募者データ!$Q$3:$Q$504,"採用")+COUNTIFS(応募者データ!$B$3:$B$504,"バイトル",応募者データ!$Q$3:$Q$504,"入社予定") -> 0
B29: マイナビバイト | C29: =COUNTIFS(応募者データ!$B$3:$B$504,"マイナビバイト") -> 3 | D29: =COUNTIFS(応募者データ!$B$3:$B$504,"マイナビバイト",応募者データ!$K$3:$K$504,"通過") -> 1 | E29: =COUNTIFS(応募者データ!$B$3:$B$504,"マイナビバイト",応募者データ!$N$3:$N$504,"面接調整中")+COUNTIFS(応募者データ!$B$3:$B$504,"マイナビバイト",応募者データ!$N$3:$N$504,"面接日確定")+COUNTIFS(応募者データ!$B$3:$B$504,"マイナビバイト",応募者データ!$N$3:$N$504,"面接実施済み") -> 1 | F29: =COUNTIFS(応募者データ!$B$3:$B$504,"マイナビバイト",応募者データ!$N$3:$N$504,"面接実施済み") -> 0 | G29: =COUNTIFS(応募者データ!$B$3:$B$504,"マイナビバイト",応募者データ!$Q$3:$Q$504,"採用")+COUNTIFS(応募者データ!$B$3:$B$504,"マイナビバイト",応募者データ!$Q$3:$Q$504,"入社予定")+COUNTIFS(応募者データ!$B$3:$B$504,"マイナビバイト",応募者データ!$Q$3:$Q$504,"採用辞退")+COUNTIFS(応募者データ!$B$3:$B$504,"マイナビバイト",応募者データ!$Q$3:$Q$504,"入社辞退") -> 0 | H29: =COUNTIFS(応募者データ!$B$3:$B$504,"マイナビバイト",応募者データ!$Q$3:$Q$504,"採用")+COUNTIFS(応募者データ!$B$3:$B$504,"マイナビバイト",応募者データ!$Q$3:$Q$504,"入社予定") -> 0
B30: ちゃんと | C30: =COUNTIFS(応募者データ!$B$3:$B$504,"ちゃんと") -> 0 | D30: =COUNTIFS(応募者データ!$B$3:$B$504,"ちゃんと",応募者データ!$K$3:$K$504,"通過") -> 0 | E30: =COUNTIFS(応募者データ!$B$3:$B$504,"ちゃんと",応募者データ!$N$3:$N$504,"面接調整中")+COUNTIFS(応募者データ!$B$3:$B$504,"ちゃんと",応募者データ!$N$3:$N$504,"面接日確定")+COUNTIFS(応募者データ!$B$3:$B$504,"ちゃんと",応募者データ!$N$3:$N$504,"面接実施済み") -> 0 | F30: =COUNTIFS(応募者データ!$B$3:$B$504,"ちゃんと",応募者データ!$N$3:$N$504,"面接実施済み") -> 0 | G30: =COUNTIFS(応募者データ!$B$3:$B$504,"ちゃんと",応募者データ!$Q$3:$Q$504,"採用")+COUNTIFS(応募者データ!$B$3:$B$504,"ちゃんと",応募者データ!$Q$3:$Q$504,"入社予定")+COUNTIFS(応募者データ!$B$3:$B$504,"ちゃんと",応募者データ!$Q$3:$Q$504,"採用辞退")+COUNTIFS(応募者データ!$B$3:$B$504,"ちゃんと",応募者データ!$Q$3:$Q$504,"入社辞退") -> 0 | H30: =COUNTIFS(応募者データ!$B$3:$B$504,"ちゃんと",応募者データ!$Q$3:$Q$504,"採用")+COUNTIFS(応募者データ!$B$3:$B$504,"ちゃんと",応募者データ!$Q$3:$Q$504,"入社予定") -> 0
B31: 社員紹介 | C31: =COUNTIFS(応募者データ!$B$3:$B$504,"社員紹介") -> 0 | D31: =COUNTIFS(応募者データ!$B$3:$B$504,"社員紹介",応募者データ!$K$3:$K$504,"通過") -> 0 | E31: =COUNTIFS(応募者データ!$B$3:$B$504,"社員紹介",応募者データ!$N$3:$N$504,"面接調整中")+COUNTIFS(応募者データ!$B$3:$B$504,"社員紹介",応募者データ!$N$3:$N$504,"面接日確定")+COUNTIFS(応募者データ!$B$3:$B$504,"社員紹介",応募者データ!$N$3:$N$504,"面接実施済み") -> 0 | F31: =COUNTIFS(応募者データ!$B$3:$B$504,"社員紹介",応募者データ!$N$3:$N$504,"面接実施済み") -> 0 | G31: =COUNTIFS(応募者データ!$B$3:$B$504,"社員紹介",応募者データ!$Q$3:$Q$504,"採用")+COUNTIFS(応募者データ!$B$3:$B$504,"社員紹介",応募者データ!$Q$3:$Q$504,"入社予定")+COUNTIFS(応募者データ!$B$3:$B$504,"社員紹介",応募者データ!$Q$3:$Q$504,"採用辞退")+COUNTIFS(応募者データ!$B$3:$B$504,"社員紹介",応募者データ!$Q$3:$Q$504,"入社辞退") -> 0 | H31: =COUNTIFS(応募者データ!$B$3:$B$504,"社員紹介",応募者データ!$Q$3:$Q$504,"採用")+COUNTIFS(応募者データ!$B$3:$B$504,"社員紹介",応募者データ!$Q$3:$Q$504,"入社予定") -> 0
B32: HP | C32: =COUNTIFS(応募者データ!$B$3:$B$504,"HP") -> 0 | D32: =COUNTIFS(応募者データ!$B$3:$B$504,"HP",応募者データ!$K$3:$K$504,"通過") -> 0 | E32: =COUNTIFS(応募者データ!$B$3:$B$504,"HP",応募者データ!$N$3:$N$504,"面接調整中")+COUNTIFS(応募者データ!$B$3:$B$504,"HP",応募者データ!$N$3:$N$504,"面接日確定")+COUNTIFS(応募者データ!$B$3:$B$504,"HP",応募者データ!$N$3:$N$504,"面接実施済み") -> 0 | F32: =COUNTIFS(応募者データ!$B$3:$B$504,"HP",応募者データ!$N$3:$N$504,"面接実施済み") -> 0 | G32: =COUNTIFS(応募者データ!$B$3:$B$504,"HP",応募者データ!$Q$3:$Q$504,"採用")+COUNTIFS(応募者データ!$B$3:$B$504,"HP",応募者データ!$Q$3:$Q$504,"入社予定")+COUNTIFS(応募者データ!$B$3:$B$504,"HP",応募者データ!$Q$3:$Q$504,"採用辞退")+COUNTIFS(応募者データ!$B$3:$B$504,"HP",応募者データ!$Q$3:$Q$504,"入社辞退") -> 0 | H32: =COUNTIFS(応募者データ!$B$3:$B$504,"HP",応募者データ!$Q$3:$Q$504,"採用")+COUNTIFS(応募者データ!$B$3:$B$504,"HP",応募者データ!$Q$3:$Q$504,"入社予定") -> 0
B33: ナリタjobサポート | C33: =COUNTIFS(応募者データ!$B$3:$B$504,"ナリタjobサポート") -> 1 | D33: =COUNTIFS(応募者データ!$B$3:$B$504,"ナリタjobサポート",応募者データ!$K$3:$K$504,"通過") -> 1 | E33: =COUNTIFS(応募者データ!$B$3:$B$504,"ナリタjobサポート",応募者データ!$N$3:$N$504,"面接調整中")+COUNTIFS(応募者データ!$B$3:$B$504,"ナリタjobサポート",応募者データ!$N$3:$N$504,"面接日確定")+COUNTIFS(応募者データ!$B$3:$B$504,"ナリタjobサポート",応募者データ!$N$3:$N$504,"面接実施済み") -> 1 | F33: =COUNTIFS(応募者データ!$B$3:$B$504,"ナリタjobサポート",応募者データ!$N$3:$N$504,"面接実施済み") -> 0 | G33: =COUNTIFS(応募者データ!$B$3:$B$504,"ナリタjobサポート",応募者データ!$Q$3:$Q$504,"採用")+COUNTIFS(応募者データ!$B$3:$B$504,"ナリタjobサポート",応募者データ!$Q$3:$Q$504,"入社予定")+COUNTIFS(応募者データ!$B$3:$B$504,"ナリタjobサポート",応募者データ!$Q$3:$Q$504,"採用辞退")+COUNTIFS(応募者データ!$B$3:$B$504,"その他",応募者データ!$Q$3:$Q$504,"入社辞退") -> 0 | H33: =COUNTIFS(応募者データ!$B$3:$B$504,"ナリタjobサポート",応募者データ!$Q$3:$Q$504,"採用")+COUNTIFS(応募者データ!$B$3:$B$504,"ナリタjobサポート",応募者データ!$Q$3:$Q$504,"入社予定") -> 0
B34: その他 | C34: =COUNTIFS(応募者データ!$B$3:$B$504,"その他") -> 0 | D34: =COUNTIFS(応募者データ!$B$3:$B$504,"その他",応募者データ!$K$3:$K$504,"通過") -> 0 | E34: =COUNTIFS(応募者データ!$B$3:$B$504,"その他",応募者データ!$N$3:$N$504,"面接調整中")+COUNTIFS(応募者データ!$B$3:$B$504,"その他",応募者データ!$N$3:$N$504,"面接日確定")+COUNTIFS(応募者データ!$B$3:$B$504,"その他",応募者データ!$N$3:$N$504,"面接実施済み") -> 0 | F34: =COUNTIFS(応募者データ!$B$3:$B$504,"その他",応募者データ!$N$3:$N$504,"面接実施済み") -> 0 | G34: =COUNTIFS(応募者データ!$B$3:$B$504,"その他",応募者データ!$Q$3:$Q$504,"採用")+COUNTIFS(応募者データ!$B$3:$B$504,"その他",応募者データ!$Q$3:$Q$504,"入社予定")+COUNTIFS(応募者データ!$B$3:$B$504,"その他",応募者データ!$Q$3:$Q$504,"採用辞退")+COUNTIFS(応募者データ!$B$3:$B$504,"その他",応募者データ!$Q$3:$Q$504,"入社辞退") -> 0 | H34: =COUNTIFS(応募者データ!$B$3:$B$504,"その他",応募者データ!$Q$3:$Q$504,"採用")+COUNTIFS(応募者データ!$B$3:$B$504,"その他",応募者データ!$Q$3:$Q$504,"入社予定") -> 0
B35: 合計 | C35: =SUM(C28:C33) -> 20 | D35: =SUM(D28:D33) -> 4 | E35: =SUM(E28:E33) -> 4 | F35: =SUM(F28:F33) -> 1 | G35: =SUM(G28:G33) -> 0 | H35: =SUM(H28:H33) -> 0
B37: ④ 基地別 実績（NRT=成田 / CTS=千歳）
B38: 基地 | C38: 応募数 | D38: 書類通過 | E38: 面接設定 | F38: 面接実施 | G38: 内定 | H38: 承諾
B39: NRT（成田） | C39: =COUNTIFS(応募者データ!$C$3:$C$504,"NRT") -> 15 | D39: =COUNTIFS(応募者データ!$C$3:$C$504,"NRT",応募者データ!$K$3:$K$504,"通過") -> 3 | E39: =COUNTIFS(応募者データ!$C$3:$C$504,"NRT",応募者データ!$N$3:$N$504,"面接調整中")+COUNTIFS(応募者データ!$C$3:$C$504,"NRT",応募者データ!$N$3:$N$504,"面接日確定")+COUNTIFS(応募者データ!$C$3:$C$504,"NRT",応募者データ!$N$3:$N$504,"面接実施済み") -> 3 | F39: =COUNTIFS(応募者データ!$C$3:$C$504,"NRT",応募者データ!$N$3:$N$504,"面接実施済み") -> 1 | G39: =COUNTIFS(応募者データ!$C$3:$C$504,"NRT",応募者データ!$Q$3:$Q$504,"採用")+COUNTIFS(応募者データ!$C$3:$C$504,"NRT",応募者データ!$Q$3:$Q$504,"入社予定")+COUNTIFS(応募者データ!$C$3:$C$504,"NRT",応募者データ!$Q$3:$Q$504,"採用辞退")+COUNTIFS(応募者データ!$C$3:$C$504,"NRT",応募者データ!$Q$3:$Q$504,"入社辞退") -> 0 | H39: =COUNTIFS(応募者データ!$C$3:$C$504,"NRT",応募者データ!$Q$3:$Q$504,"採用")+COUNTIFS(応募者データ!$C$3:$C$504,"NRT",応募者データ!$Q$3:$Q$504,"入社予定") -> 0
B40: CTS（千歳） | C40: =COUNTIFS(応募者データ!$C$3:$C$504,"CTS") -> 5 | D40: =COUNTIFS(応募者データ!$C$3:$C$504,"CTS",応募者データ!$K$3:$K$504,"通過") -> 1 | E40: =COUNTIFS(応募者データ!$C$3:$C$504,"CTS",応募者データ!$N$3:$N$504,"面接調整中")+COUNTIFS(応募者データ!$C$3:$C$504,"CTS",応募者データ!$N$3:$N$504,"面接日確定")+COUNTIFS(応募者データ!$C$3:$C$504,"CTS",応募者データ!$N$3:$N$504,"面接実施済み") -> 1 | F40: =COUNTIFS(応募者データ!$C$3:$C$504,"CTS",応募者データ!$N$3:$N$504,"面接実施済み") -> 0 | G40: =COUNTIFS(応募者データ!$C$3:$C$504,"CTS",応募者データ!$Q$3:$Q$504,"採用")+COUNTIFS(応募者データ!$C$3:$C$504,"CTS",応募者データ!$Q$3:$Q$504,"入社予定")+COUNTIFS(応募者データ!$C$3:$C$504,"CTS",応募者データ!$Q$3:$Q$504,"採用辞退")+COUNTIFS(応募者データ!$C$3:$C$504,"CTS",応募者データ!$Q$3:$Q$504,"入社辞退") -> 0 | H40: =COUNTIFS(応募者データ!$C$3:$C$504,"CTS",応募者データ!$Q$3:$Q$504,"採用")+COUNTIFS(応募者データ!$C$3:$C$504,"CTS",応募者データ!$Q$3:$Q$504,"入社予定") -> 0
B42: ⑤ 拠点別 採用目標 達成状況（承諾＝採用人数）
B43: 拠点 | C43: 採用目標 | D43: 承諾実績 | E43: 達成率
B44: NRT（成田） | C44: =$D$5 -> 10 | D44: =H39 -> 0 | E44: =IFERROR(H39/$D$5,"") -> 0
B45: CTS（千歳） | C45: =$F$5 -> 10 | D45: =H40 -> 0 | E45: =IFERROR(H40/$F$5,"") -> 0
B46: 合計 | C46: =$H$5 -> 20 | D46: =H39+H40 -> 0 | E46: =IFERROR((H39+H40)/$H$5,"") -> 0
...

Sheet 日次レポート
A1: 日次レポート（毎日 EOD に担当者が1行追記）
A2: 使い方：応募者データを更新後、当日の累計値を下表に1行追記します（右の「現在の累計値」を転記でOK）。ダッシュボードの前日比・推移グラフに自動反映されます。灰色の行はサンプルです。実データ入力時に削除してください。
A3: 日付 | B3: 応募数 | C3: 書類通過 | D3: 面接設定 | E3: 面接実施 | F3: 内定 | G3: 承諾 | H3: 担当者 | I3: 備考 | K3: 現在の累計値（自動）
A4: 46230 | B4: 1 | C4: 0 | D4: 0 | E4: 0 | F4: 0 | G4: 0 | H4: 遠藤 | I4: ← サンプル：削除して実データを入力 | K4: 応募数 | L4: =COUNTA(応募者データ!$E$3:$E$504) -> 20
A5: 46231 | B5: 2 | C5: 0 | D5: 0 | E5: 0 | F5: 0 | G5: 0 | H5: 遠藤 | K5: 書類通過 | L5: =COUNTIF(応募者データ!$K$3:$K$504,"通過") -> 4
A6: 46232 | B6: 1 | C6: 1 | D6: 0 | E6: 0 | F6: 0 | G6: 0 | H6: 遠藤 | K6: 面接設定 | L6: =COUNTIF(応募者データ!$N$3:$N$504,"面接調整中")+COUNTIF(応募者データ!$N$3:$N$504,"面接日確定")+COUNTIF(応募者データ!$N$3:$N$504,"面接実施済み") -> 4
A7: 46233 | B7: 5 | C7: 1 | D7: 0 | E7: 0 | F7: 0 | G7: 0 | H7: 遠藤 | K7: 面接実施 | L7: =COUNTIF(応募者データ!$N$3:$N$504,"面接実施済み") -> 1
A8: 46234 | B8: 0 | C8: 0 | D8: 0 | E8: 0 | F8: 0 | G8: 0 | H8: 遠藤 | K8: 内定 | L8: =COUNTIF(応募者データ!$Q$3:$Q$504,"採用")+COUNTIF(応募者データ!$Q$3:$Q$504,"入社予定")+COUNTIF(応募者データ!$Q$3:$Q$504,"採用辞退")+COUNTIF(応募者データ!$Q$3:$Q$504,"入社辞退") -> 0
A9: 46235 | B9: 0 | C9: 0 | D9: 0 | E9: 0 | F9: 0 | G9: 0 | H9: 遠藤 | K9: 承諾 | L9: =COUNTIF(応募者データ!$Q$3:$Q$504,"採用")+COUNTIF(応募者データ!$Q$3:$Q$504,"入社予定") -> 0
A10: 46236 | B10: 3 | C10: 0 | D10: 0 | E10: 0 | F10: 0 | G10: 0 | H10: 遠藤
A11: 46237 | B11: 2 | C11: 1 | D11: 1 | E11: 0 | F11: 0 | G11: 0 | H11: 遠藤
A12: 46238 | B12: 0 | C12: 0 | D12: 0 | E12: 1 | F12: 0 | G12: 0 | H12: 遠藤
A13: 46239 | B13: 0 | C13: 0 | D13: 0 | E13: 0 | F13: 0 | G13: 0 | H13: 遠藤
A14: 46240 | B14: 1 | C14: 0 | D14: 0 | E14: 0 | F14: 0 | G14: 0 | H14: 遠藤

Sheet 応募者データ
A1: 応募者データ（明細） ― 毎日ここを更新。ダッシュボード・社長報告は自動集計されます ―
A2: No. | B2: 媒体 | C2: 基地 | D2: 応募日 | E2: 氏名 | F2: 年齢 | G2: 性別 | H2: 国籍 | I2: 経験 | J2: 属性 | K2: 書類選考 | L2: 履歴書回収 | M2: 書類NG理由 | N2: 面接 | O2: 面接日 | P2: 面接NG理由 | Q2: 採用 | R2: 入社予定日 | S2: 承諾状況 | T2: 内定通知 | U2: 備考
A3: 1 | B3: バイトル | C3: NRT | D3: 46227 | E3: 日高 秀光 | F3: 73 | G3: 男 | H3: 日本 | I3: 未経験者 | J3: 主婦・主夫 | K3: 不通過 | M3: 年齢 | N3: 未設定 | Q3: 不採用
A4: 2 | B4: バイトル | C4: NRT | D4: 46230 | E4: 浅利 真弓 | F4: 63 | G4: 女 | H4: 日本 | I4: 未経験者 | J4: 無職 | K4: 不通過 | M4: 年齢 | N4: 未設定 | Q4: 不採用
A5: 3 | B5: バイトル | C5: NRT | D5: 46231 | E5: 浅木 洋二 | F5: 76 | G5: 男 | H5: 日本 | I5: 未経験者 | J5: その他 | K5: 不通過 | M5: 年齢 | N5: 未設定 | Q5: 不採用
A6: 4 | B6: バイトル | C6: NRT | D6: 46231 | E6: 佐伯 幸男 | F6: 55 | G6: 男 | H6: 日本 | I6: 未経験者 | J6: アルバイト | K6: 不通過 | M6: 年齢 | N6: 未設定 | Q6: 不採用
A7: 5 | B7: バイトル | C7: NRT | D7: 46232 | E7: 町田 侑里夏 | F7: 21 | G7: 女 | H7: 日本 | I7: 未経験者 | J7: 大学生 | K7: 通過 | N7: 面接実施済み | P7: 接客適性 | Q7: 不採用 | U7: ７日間の研修参加が難しい。
A8: 6 | B8: バイトル | C8: NRT | D8: 46233 | E8: 三木 祐樹 | F8: 38 | G8: 男 | H8: 日本 | I8: 未経験者 | J8: アルバイト | K8: 不通過 | M8: 年齢 | N8: 未設定 | Q8: 不採用
A9: 7 | B9: バイトル | C9: NRT | D9: 46233 | E9: 金澤 拓也 | F9: 19 | G9: 男 | H9: 日本 | I9: 未経験者 | J9: 大学生 | K9: 通過 | N9: 面接日確定 | Q9: 選考中 | U9: 8/12WEB面接予定
A10: 8 | B10: バイトル | C10: NRT | D10: 46233 | E10: NGUYEN NGOC DINH | F10: 25 | G10: 男 | H10: 外国籍 | I10: 未経験者 | J10: 主婦・主夫 | K10: 不通過 | M10: 日本語力 | N10: 未設定 | Q10: 不採用 | U10: N3
A11: 9 | B11: バイトル | C11: NRT | D11: 46236 | E11: Hashini Navodya | F11: 21 | G11: 女 | H11: 外国籍 | I11: 未経験者 | J11: アルバイト | K11: 不通過 | M11: 日本語力 | N11: 未設定 | Q11: 選考中 | U11: CTS同時応募
A12: 10 | B12: バイトル | C12: NRT | D12: 46236 | E12: JARGALBAYAR ENKHBAYAN | F12: 21 | G12: 男 | H12: 外国籍 | I12: 未経験者 | J12: 大学生 | K12: 不通過 | M12: 日本語力 | N12: 未設定 | Q12: 選考中
A13: 11 | B13: バイトル | C13: NRT | D13: 46237 | E13: 坂本 隼斗 | F13: 24 | G13: 男 | H13: 日本 | I13: 未経験者 | J13: 大学生 | K13: 確認中 | N13: 未設定 | Q13: 選考中 | U13: 履歴書依頼中
A14: 12 | B14: バイトル | C14: CTS | D14: 46236 | E14: Hashini Navodya | F14: 21 | G14: 女 | H14: 外国籍 | I14: 未経験者 | J14: その他 | K14: 不通過 | M14: 日本語力 | N14: 未設定 | Q14: 選考中 | U14: NRT同時応募
A15: 13 | B15: マイナビバイト | C15: CTS | D15: 46233 | E15: 竹内 愛 | F15: 33 | G15: 女 | H15: 日本 | I15: 未経験者 | J15: その他 | K15: 確認中 | N15: 未設定 | Q15: 選考中
A16: 14 | B16: マイナビバイト | C16: CTS | D16: 46233 | E16: 高砂 琴音 | F16: 18 | G16: 女 | H16: 日本 | I16: 未経験者 | J16: その他 | K16: 確認中 | N16: 未設定 | Q16: 選考中 | U16: 高校生（外航GATE経験者の可能性あり）
A17: 15 | B17: マイナビバイト | C17: CTS | D17: 46238 | E17: 星山 瑠衣 | F17: 25 | G17: 男 | H17: 日本 | I17: 未経験者 | J17: アルバイト | K17: 通過 | N17: 面接日確定 | Q17: 選考中 | U17: 8/10WEB面接予定
A18: 16 | B18: ナリタjobサポート | C18: NRT | D18: 46237 | E18: 石塚 亜也 | F18: 28 | G18: 女 | H18: 日本 | I18: 経験者 | J18: アルバイト | K18: 通過 | N18: 面接日確定 | Q18: 選考中 | U18: ナリタjobポート木村さん経由
A19: 17 | B19: バイトル | C19: NRT | D19: 46240 | E19: 小瀧 紅 | F19: 62 | G19: 女 | H19: 日本 | I19: 未経験者 | J19: パート | K19: 不通過 | M19: 年齢 | N19: 未設定 | Q19: 選考中
A20: 18 | B20: バイトル | C20: NRT | D20: 46240 | E20: 椎名 睦季 | F20: 18 | G20: 男 | H20: 日本 | I20: 未経験者 | J20: 大学生 | K20: 確認中 | N20: 未設定 | Q20: 選考中
A21: 19 | B21: バイトル | C21: CTS | D21: 46240 | E21: 関 恵実 | F21: 17 | G21: 女 | H21: 日本 | I21: 未経験者
A22: 20 | B22: バイトル | C22: NRT | D22: 46241 | E22: 山田 伸 | F22: 77 | G22: 男 | H22: 日本 | I22: 未経験者
A23: 21
A24: 22
A25: 23
A26: 24
A27: 25
A28: 26
A29: 27
A30: 28
A31: 29
A32: 30
A33: 31

Sheet マスタ
A1: マスタ（プルダウン用リスト）
A2: 媒体 | B2: 基地 | C2: 性別 | D2: 国籍 | E2: 経験 | F2: 属性 | G2: 書類選考 | H2: 書類NG理由 | I2: 面接 | J2: 面接NG理由 | K2: 採用 | L2: 履歴書回収 | M2: 承諾状況 | N2: 内定通知
A3: バイトル | B3: NRT | C3: 男 | D3: 日本 | E3: 経験者 | F3: 大学生 | G3: 未対応 | H3: 年齢 | I3: 未設定 | J3: 勤務条件不一致 | K3: 選考中 | L3: 有 | M3: 承諾済み | N3: 未
A4: マイナビバイト | B4: CTS | C4: 女 | D4: 外国籍 | E4: 未経験者 | F4: フリーター | G4: 確認中 | H4: 通勤距離 | I4: 面接調整中 | J4: シフト条件不一致 | K4: 採用 | L4: 無 | M4: 辞退 | N4: 済
A5: ちゃんと | F5: 社会人 | G5: 通過 | H5: 国籍 | I5: 面接日確定 | J5: 経験不足 | K5: 不採用 | M5: 保留
A6: 社員紹介 | F6: 主婦・主夫 | G6: 保留 | H6: 日本語力 | I6: 面接実施済み | J6: 接客適性 | K6: 採用辞退
A7: HP | F7: 無職 | G7: 不通過 | H7: 英語力 | J7: コミュニケーション | K7: 入社予定
A8: ナリタjobサポート | F8: 高校生 | G8: 辞退 | H8: 勤務時間不一致 | J8: 日本語力 | K8: 入社辞退
A9: Indeed | F9: アルバイト | G9: 連絡不通 | H9: その他 | J9: 英語力 | K9: 保留
A10: ハローワーク | F10: パート | J10: 航空保安上の要件
A11: その他 | F11: その他 | J11: 通勤困難
J12: 給与条件不一致
J13: 入社可能時期が合わない
J14: 他社内定
J15: 本人辞退
J16: 総合判断
J17: その他
